[2024-07-29 20:08:28 +0200] [61220] [INFO] Starting gunicorn 22.0.0
[2024-07-29 20:08:28 +0200] [61220] [INFO] Listening at: http://0.0.0.0:5000 (61220)
[2024-07-29 20:08:28 +0200] [61220] [INFO] Using worker: sync
[2024-07-29 20:08:28 +0200] [61222] [INFO] Booting worker with pid: 61222
[2024-07-29 20:08:28 +0200] [61223] [INFO] Booting worker with pid: 61223
[2024-07-29 20:08:28 +0200] [61224] [INFO] Booting worker with pid: 61224
[2024-07-29 20:36:37 +0200] [61220] [INFO] Handling signal: term
[2024-07-29 20:36:37 +0200] [61222] [INFO] Worker exiting (pid: 61222)
[2024-07-29 20:36:37 +0200] [61224] [INFO] Worker exiting (pid: 61224)
[2024-07-29 20:36:37 +0200] [61223] [INFO] Worker exiting (pid: 61223)
[2024-07-29 20:36:38 +0200] [61220] [INFO] Shutting down: Master
[2024-07-29 20:36:38 +0200] [61870] [INFO] Starting gunicorn 22.0.0
[2024-07-29 20:36:38 +0200] [61870] [INFO] Listening at: http://0.0.0.0:5000 (61870)
[2024-07-29 20:36:38 +0200] [61870] [INFO] Using worker: sync
[2024-07-29 20:36:38 +0200] [61872] [INFO] Booting worker with pid: 61872
[2024-07-29 20:36:38 +0200] [61873] [INFO] Booting worker with pid: 61873
[2024-07-29 20:36:38 +0200] [61874] [INFO] Booting worker with pid: 61874
[2024-07-29 20:36:38 +0200] [61872] [ERROR] Exception in worker process
Traceback (most recent call last):
  File "/root/csk-env/lib/python3.11/site-packages/gunicorn/arbiter.py", line 609, in spawn_worker
    worker.init_process()
  File "/root/csk-env/lib/python3.11/site-packages/gunicorn/workers/base.py", line 134, in init_process
    self.load_wsgi()
  File "/root/csk-env/lib/python3.11/site-packages/gunicorn/workers/base.py", line 146, in load_wsgi
    self.wsgi = self.app.wsgi()
                ^^^^^^^^^^^^^^^
  File "/root/csk-env/lib/python3.11/site-packages/gunicorn/app/base.py", line 67, in wsgi
    self.callable = self.load()
                    ^^^^^^^^^^^
  File "/root/csk-env/lib/python3.11/site-packages/gunicorn/app/wsgiapp.py", line 58, in load
    return self.load_wsgiapp()
           ^^^^^^^^^^^^^^^^^^^
  File "/root/csk-env/lib/python3.11/site-packages/gunicorn/app/wsgiapp.py", line 48, in load_wsgiapp
    return util.import_app(self.app_uri)
           ^^^^^^^^^^^^^^^^^^^^^^^^^^^^^
  File "/root/csk-env/lib/python3.11/site-packages/gunicorn/util.py", line 371, in import_app
    mod = importlib.import_module(module)
          ^^^^^^^^^^^^^^^^^^^^^^^^^^^^^^^
  File "/usr/lib/python3.11/importlib/__init__.py", line 126, in import_module
    return _bootstrap._gcd_import(name[level:], package, level)
           ^^^^^^^^^^^^^^^^^^^^^^^^^^^^^^^^^^^^^^^^^^^^^^^^^^^^
  File "<frozen importlib._bootstrap>", line 1204, in _gcd_import
  File "<frozen importlib._bootstrap>", line 1176, in _find_and_load
  File "<frozen importlib._bootstrap>", line 1147, in _find_and_load_unlocked
  File "<frozen importlib._bootstrap>", line 690, in _load_unlocked
  File "<frozen importlib._bootstrap_external>", line 940, in exec_module
  File "<frozen importlib._bootstrap>", line 241, in _call_with_frames_removed
  File "/root/csk-main/app.py", line 3, in <module>
    from api.v1.blueprints import api
  File "/root/csk-main/api/v1/blueprints/__init__.py", line 10, in <module>
    from api.v1.blueprints.post import *
  File "/root/csk-main/api/v1/blueprints/post.py", line 101
    return "", 204
IndentationError: unexpected indent
[2024-07-29 20:36:38 +0200] [61872] [INFO] Worker exiting (pid: 61872)
[2024-07-29 20:36:39 +0200] [61870] [ERROR] Worker (pid:61872) exited with code 3
[2024-07-29 20:36:39 +0200] [61873] [ERROR] Exception in worker process
Traceback (most recent call last):
  File "/root/csk-env/lib/python3.11/site-packages/gunicorn/arbiter.py", line 609, in spawn_worker
    worker.init_process()
  File "/root/csk-env/lib/python3.11/site-packages/gunicorn/workers/base.py", line 134, in init_process
    self.load_wsgi()
  File "/root/csk-env/lib/python3.11/site-packages/gunicorn/workers/base.py", line 146, in load_wsgi
    self.wsgi = self.app.wsgi()
                ^^^^^^^^^^^^^^^
  File "/root/csk-env/lib/python3.11/site-packages/gunicorn/app/base.py", line 67, in wsgi
    self.callable = self.load()
                    ^^^^^^^^^^^
  File "/root/csk-env/lib/python3.11/site-packages/gunicorn/app/wsgiapp.py", line 58, in load
    return self.load_wsgiapp()
           ^^^^^^^^^^^^^^^^^^^
  File "/root/csk-env/lib/python3.11/site-packages/gunicorn/app/wsgiapp.py", line 48, in load_wsgiapp
    return util.import_app(self.app_uri)
           ^^^^^^^^^^^^^^^^^^^^^^^^^^^^^
  File "/root/csk-env/lib/python3.11/site-packages/gunicorn/util.py", line 371, in import_app
    mod = importlib.import_module(module)
          ^^^^^^^^^^^^^^^^^^^^^^^^^^^^^^^
  File "/usr/lib/python3.11/importlib/__init__.py", line 126, in import_module
    return _bootstrap._gcd_import(name[level:], package, level)
           ^^^^^^^^^^^^^^^^^^^^^^^^^^^^^^^^^^^^^^^^^^^^^^^^^^^^
  File "<frozen importlib._bootstrap>", line 1204, in _gcd_import
  File "<frozen importlib._bootstrap>", line 1176, in _find_and_load
  File "<frozen importlib._bootstrap>", line 1147, in _find_and_load_unlocked
  File "<frozen importlib._bootstrap>", line 690, in _load_unlocked
  File "<frozen importlib._bootstrap_external>", line 940, in exec_module
  File "<frozen importlib._bootstrap>", line 241, in _call_with_frames_removed
  File "/root/csk-main/app.py", line 3, in <module>
    from api.v1.blueprints import api
  File "/root/csk-main/api/v1/blueprints/__init__.py", line 10, in <module>
    from api.v1.blueprints.post import *
  File "/root/csk-main/api/v1/blueprints/post.py", line 101
    return "", 204
IndentationError: unexpected indent
[2024-07-29 20:36:39 +0200] [61873] [INFO] Worker exiting (pid: 61873)
[2024-07-29 20:36:39 +0200] [61874] [ERROR] Exception in worker process
Traceback (most recent call last):
  File "/root/csk-env/lib/python3.11/site-packages/gunicorn/arbiter.py", line 609, in spawn_worker
    worker.init_process()
  File "/root/csk-env/lib/python3.11/site-packages/gunicorn/workers/base.py", line 134, in init_process
    self.load_wsgi()
  File "/root/csk-env/lib/python3.11/site-packages/gunicorn/workers/base.py", line 146, in load_wsgi
    self.wsgi = self.app.wsgi()
                ^^^^^^^^^^^^^^^
  File "/root/csk-env/lib/python3.11/site-packages/gunicorn/app/base.py", line 67, in wsgi
    self.callable = self.load()
                    ^^^^^^^^^^^
  File "/root/csk-env/lib/python3.11/site-packages/gunicorn/app/wsgiapp.py", line 58, in load
    return self.load_wsgiapp()
           ^^^^^^^^^^^^^^^^^^^
  File "/root/csk-env/lib/python3.11/site-packages/gunicorn/app/wsgiapp.py", line 48, in load_wsgiapp
    return util.import_app(self.app_uri)
           ^^^^^^^^^^^^^^^^^^^^^^^^^^^^^
  File "/root/csk-env/lib/python3.11/site-packages/gunicorn/util.py", line 371, in import_app
    mod = importlib.import_module(module)
          ^^^^^^^^^^^^^^^^^^^^^^^^^^^^^^^
  File "/usr/lib/python3.11/importlib/__init__.py", line 126, in import_module
    return _bootstrap._gcd_import(name[level:], package, level)
           ^^^^^^^^^^^^^^^^^^^^^^^^^^^^^^^^^^^^^^^^^^^^^^^^^^^^
  File "<frozen importlib._bootstrap>", line 1204, in _gcd_import
  File "<frozen importlib._bootstrap>", line 1176, in _find_and_load
  File "<frozen importlib._bootstrap>", line 1147, in _find_and_load_unlocked
  File "<frozen importlib._bootstrap>", line 690, in _load_unlocked
  File "<frozen importlib._bootstrap_external>", line 940, in exec_module
  File "<frozen importlib._bootstrap>", line 241, in _call_with_frames_removed
  File "/root/csk-main/app.py", line 3, in <module>
    from api.v1.blueprints import api
  File "/root/csk-main/api/v1/blueprints/__init__.py", line 10, in <module>
    from api.v1.blueprints.post import *
  File "/root/csk-main/api/v1/blueprints/post.py", line 101
    return "", 204
IndentationError: unexpected indent
[2024-07-29 20:36:39 +0200] [61874] [INFO] Worker exiting (pid: 61874)
[2024-07-29 20:36:39 +0200] [61870] [ERROR] Worker (pid:61873) exited with code 3
[2024-07-29 20:37:43 +0200] [61884] [INFO] Starting gunicorn 22.0.0
[2024-07-29 20:37:43 +0200] [61884] [INFO] Listening at: http://0.0.0.0:5000 (61884)
[2024-07-29 20:37:43 +0200] [61884] [INFO] Using worker: sync
[2024-07-29 20:37:43 +0200] [61885] [INFO] Booting worker with pid: 61885
[2024-07-29 20:37:43 +0200] [61886] [INFO] Booting worker with pid: 61886
[2024-07-29 20:37:43 +0200] [61887] [INFO] Booting worker with pid: 61887
[2024-07-30 11:32:52,394] ERROR in app: Exception on /api/v1/post/sale [POST]
Traceback (most recent call last):
  File "/root/csk-env/lib/python3.11/site-packages/sqlalchemy/engine/base.py", line 1910, in _execute_context
    self.dialect.do_execute(
  File "/root/csk-env/lib/python3.11/site-packages/sqlalchemy/engine/default.py", line 736, in do_execute
    cursor.execute(statement, parameters)
  File "/root/csk-env/lib/python3.11/site-packages/MySQLdb/cursors.py", line 179, in execute
    res = self._query(mogrified_query)
          ^^^^^^^^^^^^^^^^^^^^^^^^^^^^
  File "/root/csk-env/lib/python3.11/site-packages/MySQLdb/cursors.py", line 330, in _query
    db.query(q)
  File "/root/csk-env/lib/python3.11/site-packages/MySQLdb/connections.py", line 261, in query
    _mysql.connection.query(self, query)
MySQLdb.OperationalError: (1644, 'Item not found in inventory table')

The above exception was the direct cause of the following exception:

Traceback (most recent call last):
  File "/root/csk-env/lib/python3.11/site-packages/flask/app.py", line 2529, in wsgi_app
    response = self.full_dispatch_request()
               ^^^^^^^^^^^^^^^^^^^^^^^^^^^^
  File "/root/csk-env/lib/python3.11/site-packages/flask/app.py", line 1825, in full_dispatch_request
    rv = self.handle_user_exception(e)
         ^^^^^^^^^^^^^^^^^^^^^^^^^^^^^
  File "/root/csk-env/lib/python3.11/site-packages/flask/app.py", line 1823, in full_dispatch_request
    rv = self.dispatch_request()
         ^^^^^^^^^^^^^^^^^^^^^^^
  File "/root/csk-env/lib/python3.11/site-packages/flask/app.py", line 1799, in dispatch_request
    return self.ensure_sync(self.view_functions[rule.endpoint])(**view_args)
           ^^^^^^^^^^^^^^^^^^^^^^^^^^^^^^^^^^^^^^^^^^^^^^^^^^^^^^^^^^^^^^^^^
  File "/root/csk-main/api/v1/blueprints/post.py", line 84, in post_sale
    sale.save()
  File "/root/csk-main/models/base_model.py", line 34, in save
    models.storage.save()
  File "/root/csk-main/models/engine/db_engine.py", line 24, in save
    self.__session.commit()
  File "/root/csk-env/lib/python3.11/site-packages/sqlalchemy/orm/session.py", line 1454, in commit
    self._transaction.commit(_to_root=self.future)
  File "/root/csk-env/lib/python3.11/site-packages/sqlalchemy/orm/session.py", line 832, in commit
    self._prepare_impl()
  File "/root/csk-env/lib/python3.11/site-packages/sqlalchemy/orm/session.py", line 811, in _prepare_impl
    self.session.flush()
  File "/root/csk-env/lib/python3.11/site-packages/sqlalchemy/orm/session.py", line 3449, in flush
    self._flush(objects)
  File "/root/csk-env/lib/python3.11/site-packages/sqlalchemy/orm/session.py", line 3588, in _flush
    with util.safe_reraise():
  File "/root/csk-env/lib/python3.11/site-packages/sqlalchemy/util/langhelpers.py", line 70, in __exit__
    compat.raise_(
  File "/root/csk-env/lib/python3.11/site-packages/sqlalchemy/util/compat.py", line 211, in raise_
    raise exception
  File "/root/csk-env/lib/python3.11/site-packages/sqlalchemy/orm/session.py", line 3549, in _flush
    flush_context.execute()
  File "/root/csk-env/lib/python3.11/site-packages/sqlalchemy/orm/unitofwork.py", line 456, in execute
    rec.execute(self)
  File "/root/csk-env/lib/python3.11/site-packages/sqlalchemy/orm/unitofwork.py", line 630, in execute
    util.preloaded.orm_persistence.save_obj(
  File "/root/csk-env/lib/python3.11/site-packages/sqlalchemy/orm/persistence.py", line 245, in save_obj
    _emit_insert_statements(
  File "/root/csk-env/lib/python3.11/site-packages/sqlalchemy/orm/persistence.py", line 1097, in _emit_insert_statements
    c = connection._execute_20(
        ^^^^^^^^^^^^^^^^^^^^^^^
  File "/root/csk-env/lib/python3.11/site-packages/sqlalchemy/engine/base.py", line 1710, in _execute_20
    return meth(self, args_10style, kwargs_10style, execution_options)
           ^^^^^^^^^^^^^^^^^^^^^^^^^^^^^^^^^^^^^^^^^^^^^^^^^^^^^^^^^^^
  File "/root/csk-env/lib/python3.11/site-packages/sqlalchemy/sql/elements.py", line 334, in _execute_on_connection
    return connection._execute_clauseelement(
           ^^^^^^^^^^^^^^^^^^^^^^^^^^^^^^^^^^
  File "/root/csk-env/lib/python3.11/site-packages/sqlalchemy/engine/base.py", line 1577, in _execute_clauseelement
    ret = self._execute_context(
          ^^^^^^^^^^^^^^^^^^^^^^
  File "/root/csk-env/lib/python3.11/site-packages/sqlalchemy/engine/base.py", line 1953, in _execute_context
    self._handle_dbapi_exception(
  File "/root/csk-env/lib/python3.11/site-packages/sqlalchemy/engine/base.py", line 2134, in _handle_dbapi_exception
    util.raise_(
  File "/root/csk-env/lib/python3.11/site-packages/sqlalchemy/util/compat.py", line 211, in raise_
    raise exception
  File "/root/csk-env/lib/python3.11/site-packages/sqlalchemy/engine/base.py", line 1910, in _execute_context
    self.dialect.do_execute(
  File "/root/csk-env/lib/python3.11/site-packages/sqlalchemy/engine/default.py", line 736, in do_execute
    cursor.execute(statement, parameters)
  File "/root/csk-env/lib/python3.11/site-packages/MySQLdb/cursors.py", line 179, in execute
    res = self._query(mogrified_query)
          ^^^^^^^^^^^^^^^^^^^^^^^^^^^^
  File "/root/csk-env/lib/python3.11/site-packages/MySQLdb/cursors.py", line 330, in _query
    db.query(q)
  File "/root/csk-env/lib/python3.11/site-packages/MySQLdb/connections.py", line 261, in query
    _mysql.connection.query(self, query)
sqlalchemy.exc.OperationalError: (MySQLdb.OperationalError) (1644, 'Item not found in inventory table')
[SQL: INSERT INTO sale_weekly (id, item_name, quantity, price, user_name, payment_method, time_stamp) VALUES (%s, %s, %s, %s, %s, %s, %s)]
[parameters: ('948a85af-c752-403e-91ec-2cfdfa13097a', 'Bag ', 1, 15000, 'Muvunyi_Jimmy', 'Mobile Money', datetime.datetime(2024, 7, 30, 11, 32, 52, 391759))]
(Background on this error at: https://sqlalche.me/e/14/e3q8)
[2024-07-30 15:25:21 +0200] [61885] [INFO] Worker exiting (pid: 61885)
[2024-07-30 15:25:21 +0200] [61884] [INFO] Handling signal: term
[2024-07-30 15:25:21 +0200] [61886] [INFO] Worker exiting (pid: 61886)
[2024-07-30 15:25:21 +0200] [61887] [INFO] Worker exiting (pid: 61887)
[2024-07-30 15:25:22 +0200] [61884] [INFO] Shutting down: Master
[2024-07-30 15:25:22 +0200] [69335] [INFO] Starting gunicorn 22.0.0
[2024-07-30 15:25:22 +0200] [69335] [INFO] Listening at: http://0.0.0.0:5000 (69335)
[2024-07-30 15:25:22 +0200] [69335] [INFO] Using worker: sync
[2024-07-30 15:25:22 +0200] [69337] [INFO] Booting worker with pid: 69337
[2024-07-30 15:25:22 +0200] [69338] [INFO] Booting worker with pid: 69338
[2024-07-30 15:25:22 +0200] [69339] [INFO] Booting worker with pid: 69339
[2024-07-30 16:04:07 +0200] [69338] [INFO] Worker exiting (pid: 69338)
[2024-07-30 16:04:07 +0200] [69335] [INFO] Handling signal: term
[2024-07-30 16:04:07 +0200] [69339] [INFO] Worker exiting (pid: 69339)
[2024-07-30 16:04:07 +0200] [69337] [INFO] Worker exiting (pid: 69337)
[2024-07-30 16:04:07 +0200] [69335] [INFO] Shutting down: Master
[2024-07-30 16:04:07 +0200] [69754] [INFO] Starting gunicorn 22.0.0
[2024-07-30 16:04:07 +0200] [69754] [INFO] Listening at: http://0.0.0.0:5000 (69754)
[2024-07-30 16:04:07 +0200] [69754] [INFO] Using worker: sync
[2024-07-30 16:04:07 +0200] [69757] [INFO] Booting worker with pid: 69757
[2024-07-30 16:04:07 +0200] [69758] [INFO] Booting worker with pid: 69758
[2024-07-30 16:04:07 +0200] [69759] [INFO] Booting worker with pid: 69759
[2024-08-01 11:18:32,408] ERROR in app: Exception on /api/v1/post/sale [POST]
Traceback (most recent call last):
  File "/root/csk-env/lib/python3.11/site-packages/sqlalchemy/engine/base.py", line 1910, in _execute_context
    self.dialect.do_execute(
  File "/root/csk-env/lib/python3.11/site-packages/sqlalchemy/engine/default.py", line 736, in do_execute
    cursor.execute(statement, parameters)
  File "/root/csk-env/lib/python3.11/site-packages/MySQLdb/cursors.py", line 179, in execute
    res = self._query(mogrified_query)
          ^^^^^^^^^^^^^^^^^^^^^^^^^^^^
  File "/root/csk-env/lib/python3.11/site-packages/MySQLdb/cursors.py", line 330, in _query
    db.query(q)
  File "/root/csk-env/lib/python3.11/site-packages/MySQLdb/connections.py", line 261, in query
    _mysql.connection.query(self, query)
MySQLdb.OperationalError: (1644, 'Item not found in inventory table')

The above exception was the direct cause of the following exception:

Traceback (most recent call last):
  File "/root/csk-env/lib/python3.11/site-packages/flask/app.py", line 2529, in wsgi_app
    response = self.full_dispatch_request()
               ^^^^^^^^^^^^^^^^^^^^^^^^^^^^
  File "/root/csk-env/lib/python3.11/site-packages/flask/app.py", line 1825, in full_dispatch_request
    rv = self.handle_user_exception(e)
         ^^^^^^^^^^^^^^^^^^^^^^^^^^^^^
  File "/root/csk-env/lib/python3.11/site-packages/flask/app.py", line 1823, in full_dispatch_request
    rv = self.dispatch_request()
         ^^^^^^^^^^^^^^^^^^^^^^^
  File "/root/csk-env/lib/python3.11/site-packages/flask/app.py", line 1799, in dispatch_request
    return self.ensure_sync(self.view_functions[rule.endpoint])(**view_args)
           ^^^^^^^^^^^^^^^^^^^^^^^^^^^^^^^^^^^^^^^^^^^^^^^^^^^^^^^^^^^^^^^^^
  File "/root/csk-main/api/v1/blueprints/post.py", line 84, in post_sale
    sale.save()
  File "/root/csk-main/models/base_model.py", line 34, in save
    models.storage.save()
  File "/root/csk-main/models/engine/db_engine.py", line 24, in save
    self.__session.commit()
  File "/root/csk-env/lib/python3.11/site-packages/sqlalchemy/orm/session.py", line 1454, in commit
    self._transaction.commit(_to_root=self.future)
  File "/root/csk-env/lib/python3.11/site-packages/sqlalchemy/orm/session.py", line 832, in commit
    self._prepare_impl()
  File "/root/csk-env/lib/python3.11/site-packages/sqlalchemy/orm/session.py", line 811, in _prepare_impl
    self.session.flush()
  File "/root/csk-env/lib/python3.11/site-packages/sqlalchemy/orm/session.py", line 3449, in flush
    self._flush(objects)
  File "/root/csk-env/lib/python3.11/site-packages/sqlalchemy/orm/session.py", line 3588, in _flush
    with util.safe_reraise():
  File "/root/csk-env/lib/python3.11/site-packages/sqlalchemy/util/langhelpers.py", line 70, in __exit__
    compat.raise_(
  File "/root/csk-env/lib/python3.11/site-packages/sqlalchemy/util/compat.py", line 211, in raise_
    raise exception
  File "/root/csk-env/lib/python3.11/site-packages/sqlalchemy/orm/session.py", line 3549, in _flush
    flush_context.execute()
  File "/root/csk-env/lib/python3.11/site-packages/sqlalchemy/orm/unitofwork.py", line 456, in execute
    rec.execute(self)
  File "/root/csk-env/lib/python3.11/site-packages/sqlalchemy/orm/unitofwork.py", line 630, in execute
    util.preloaded.orm_persistence.save_obj(
  File "/root/csk-env/lib/python3.11/site-packages/sqlalchemy/orm/persistence.py", line 245, in save_obj
    _emit_insert_statements(
  File "/root/csk-env/lib/python3.11/site-packages/sqlalchemy/orm/persistence.py", line 1097, in _emit_insert_statements
    c = connection._execute_20(
        ^^^^^^^^^^^^^^^^^^^^^^^
  File "/root/csk-env/lib/python3.11/site-packages/sqlalchemy/engine/base.py", line 1710, in _execute_20
    return meth(self, args_10style, kwargs_10style, execution_options)
           ^^^^^^^^^^^^^^^^^^^^^^^^^^^^^^^^^^^^^^^^^^^^^^^^^^^^^^^^^^^
  File "/root/csk-env/lib/python3.11/site-packages/sqlalchemy/sql/elements.py", line 334, in _execute_on_connection
    return connection._execute_clauseelement(
           ^^^^^^^^^^^^^^^^^^^^^^^^^^^^^^^^^^
  File "/root/csk-env/lib/python3.11/site-packages/sqlalchemy/engine/base.py", line 1577, in _execute_clauseelement
    ret = self._execute_context(
          ^^^^^^^^^^^^^^^^^^^^^^
  File "/root/csk-env/lib/python3.11/site-packages/sqlalchemy/engine/base.py", line 1953, in _execute_context
    self._handle_dbapi_exception(
  File "/root/csk-env/lib/python3.11/site-packages/sqlalchemy/engine/base.py", line 2134, in _handle_dbapi_exception
    util.raise_(
  File "/root/csk-env/lib/python3.11/site-packages/sqlalchemy/util/compat.py", line 211, in raise_
    raise exception
  File "/root/csk-env/lib/python3.11/site-packages/sqlalchemy/engine/base.py", line 1910, in _execute_context
    self.dialect.do_execute(
  File "/root/csk-env/lib/python3.11/site-packages/sqlalchemy/engine/default.py", line 736, in do_execute
    cursor.execute(statement, parameters)
  File "/root/csk-env/lib/python3.11/site-packages/MySQLdb/cursors.py", line 179, in execute
    res = self._query(mogrified_query)
          ^^^^^^^^^^^^^^^^^^^^^^^^^^^^
  File "/root/csk-env/lib/python3.11/site-packages/MySQLdb/cursors.py", line 330, in _query
    db.query(q)
  File "/root/csk-env/lib/python3.11/site-packages/MySQLdb/connections.py", line 261, in query
    _mysql.connection.query(self, query)
sqlalchemy.exc.OperationalError: (MySQLdb.OperationalError) (1644, 'Item not found in inventory table')
[SQL: INSERT INTO sale_weekly (id, item_name, quantity, price, user_name, payment_method, time_stamp) VALUES (%s, %s, %s, %s, %s, %s, %s)]
[parameters: ('84e3e685-e024-4045-937c-fee041f122c4', 'Cap ', 1, 8000, 'Muvunyi_Jimmy', 'Cash', datetime.datetime(2024, 8, 1, 11, 18, 32, 406697))]
(Background on this error at: https://sqlalche.me/e/14/e3q8)
[2024-08-05 10:23:47,269] ERROR in app: Exception on /api/v1/post/sale [POST]
Traceback (most recent call last):
  File "/root/csk-env/lib/python3.11/site-packages/sqlalchemy/engine/base.py", line 1910, in _execute_context
    self.dialect.do_execute(
  File "/root/csk-env/lib/python3.11/site-packages/sqlalchemy/engine/default.py", line 736, in do_execute
    cursor.execute(statement, parameters)
  File "/root/csk-env/lib/python3.11/site-packages/MySQLdb/cursors.py", line 179, in execute
    res = self._query(mogrified_query)
          ^^^^^^^^^^^^^^^^^^^^^^^^^^^^
  File "/root/csk-env/lib/python3.11/site-packages/MySQLdb/cursors.py", line 330, in _query
    db.query(q)
  File "/root/csk-env/lib/python3.11/site-packages/MySQLdb/connections.py", line 261, in query
    _mysql.connection.query(self, query)
MySQLdb.OperationalError: (1644, 'Item not found in inventory table')

The above exception was the direct cause of the following exception:

Traceback (most recent call last):
  File "/root/csk-env/lib/python3.11/site-packages/flask/app.py", line 2529, in wsgi_app
    response = self.full_dispatch_request()
               ^^^^^^^^^^^^^^^^^^^^^^^^^^^^
  File "/root/csk-env/lib/python3.11/site-packages/flask/app.py", line 1825, in full_dispatch_request
    rv = self.handle_user_exception(e)
         ^^^^^^^^^^^^^^^^^^^^^^^^^^^^^
  File "/root/csk-env/lib/python3.11/site-packages/flask/app.py", line 1823, in full_dispatch_request
    rv = self.dispatch_request()
         ^^^^^^^^^^^^^^^^^^^^^^^
  File "/root/csk-env/lib/python3.11/site-packages/flask/app.py", line 1799, in dispatch_request
    return self.ensure_sync(self.view_functions[rule.endpoint])(**view_args)
           ^^^^^^^^^^^^^^^^^^^^^^^^^^^^^^^^^^^^^^^^^^^^^^^^^^^^^^^^^^^^^^^^^
  File "/root/csk-main/api/v1/blueprints/post.py", line 84, in post_sale
    sale.save()
  File "/root/csk-main/models/base_model.py", line 34, in save
    models.storage.save()
  File "/root/csk-main/models/engine/db_engine.py", line 24, in save
    self.__session.commit()
  File "/root/csk-env/lib/python3.11/site-packages/sqlalchemy/orm/session.py", line 1454, in commit
    self._transaction.commit(_to_root=self.future)
  File "/root/csk-env/lib/python3.11/site-packages/sqlalchemy/orm/session.py", line 832, in commit
    self._prepare_impl()
  File "/root/csk-env/lib/python3.11/site-packages/sqlalchemy/orm/session.py", line 811, in _prepare_impl
    self.session.flush()
  File "/root/csk-env/lib/python3.11/site-packages/sqlalchemy/orm/session.py", line 3449, in flush
    self._flush(objects)
  File "/root/csk-env/lib/python3.11/site-packages/sqlalchemy/orm/session.py", line 3588, in _flush
    with util.safe_reraise():
  File "/root/csk-env/lib/python3.11/site-packages/sqlalchemy/util/langhelpers.py", line 70, in __exit__
    compat.raise_(
  File "/root/csk-env/lib/python3.11/site-packages/sqlalchemy/util/compat.py", line 211, in raise_
    raise exception
  File "/root/csk-env/lib/python3.11/site-packages/sqlalchemy/orm/session.py", line 3549, in _flush
    flush_context.execute()
  File "/root/csk-env/lib/python3.11/site-packages/sqlalchemy/orm/unitofwork.py", line 456, in execute
    rec.execute(self)
  File "/root/csk-env/lib/python3.11/site-packages/sqlalchemy/orm/unitofwork.py", line 630, in execute
    util.preloaded.orm_persistence.save_obj(
  File "/root/csk-env/lib/python3.11/site-packages/sqlalchemy/orm/persistence.py", line 245, in save_obj
    _emit_insert_statements(
  File "/root/csk-env/lib/python3.11/site-packages/sqlalchemy/orm/persistence.py", line 1097, in _emit_insert_statements
    c = connection._execute_20(
        ^^^^^^^^^^^^^^^^^^^^^^^
  File "/root/csk-env/lib/python3.11/site-packages/sqlalchemy/engine/base.py", line 1710, in _execute_20
    return meth(self, args_10style, kwargs_10style, execution_options)
           ^^^^^^^^^^^^^^^^^^^^^^^^^^^^^^^^^^^^^^^^^^^^^^^^^^^^^^^^^^^
  File "/root/csk-env/lib/python3.11/site-packages/sqlalchemy/sql/elements.py", line 334, in _execute_on_connection
    return connection._execute_clauseelement(
           ^^^^^^^^^^^^^^^^^^^^^^^^^^^^^^^^^^
  File "/root/csk-env/lib/python3.11/site-packages/sqlalchemy/engine/base.py", line 1577, in _execute_clauseelement
    ret = self._execute_context(
          ^^^^^^^^^^^^^^^^^^^^^^
  File "/root/csk-env/lib/python3.11/site-packages/sqlalchemy/engine/base.py", line 1953, in _execute_context
    self._handle_dbapi_exception(
  File "/root/csk-env/lib/python3.11/site-packages/sqlalchemy/engine/base.py", line 2134, in _handle_dbapi_exception
    util.raise_(
  File "/root/csk-env/lib/python3.11/site-packages/sqlalchemy/util/compat.py", line 211, in raise_
    raise exception
  File "/root/csk-env/lib/python3.11/site-packages/sqlalchemy/engine/base.py", line 1910, in _execute_context
    self.dialect.do_execute(
  File "/root/csk-env/lib/python3.11/site-packages/sqlalchemy/engine/default.py", line 736, in do_execute
    cursor.execute(statement, parameters)
  File "/root/csk-env/lib/python3.11/site-packages/MySQLdb/cursors.py", line 179, in execute
    res = self._query(mogrified_query)
          ^^^^^^^^^^^^^^^^^^^^^^^^^^^^
  File "/root/csk-env/lib/python3.11/site-packages/MySQLdb/cursors.py", line 330, in _query
    db.query(q)
  File "/root/csk-env/lib/python3.11/site-packages/MySQLdb/connections.py", line 261, in query
    _mysql.connection.query(self, query)
sqlalchemy.exc.OperationalError: (MySQLdb.OperationalError) (1644, 'Item not found in inventory table')
[SQL: INSERT INTO sale_weekly (id, item_name, quantity, price, user_name, payment_method, time_stamp) VALUES (%s, %s, %s, %s, %s, %s, %s)]
[parameters: ('45ca31a9-035e-4339-b391-3774960d4784', 'Dunlop', 1, 15000, 'Muvunyi_Jimmy', 'Cash', datetime.datetime(2024, 8, 5, 10, 23, 47, 267524))]
(Background on this error at: https://sqlalche.me/e/14/e3q8)
[2024-08-19 18:04:34,527] ERROR in app: Exception on /api/v1/post/sale [POST]
Traceback (most recent call last):
  File "/root/csk-env/lib/python3.11/site-packages/sqlalchemy/engine/base.py", line 1910, in _execute_context
    self.dialect.do_execute(
  File "/root/csk-env/lib/python3.11/site-packages/sqlalchemy/engine/default.py", line 736, in do_execute
    cursor.execute(statement, parameters)
  File "/root/csk-env/lib/python3.11/site-packages/MySQLdb/cursors.py", line 179, in execute
    res = self._query(mogrified_query)
          ^^^^^^^^^^^^^^^^^^^^^^^^^^^^
  File "/root/csk-env/lib/python3.11/site-packages/MySQLdb/cursors.py", line 330, in _query
    db.query(q)
  File "/root/csk-env/lib/python3.11/site-packages/MySQLdb/connections.py", line 261, in query
    _mysql.connection.query(self, query)
MySQLdb.OperationalError: (1644, 'Item not found in inventory table')

The above exception was the direct cause of the following exception:

Traceback (most recent call last):
  File "/root/csk-env/lib/python3.11/site-packages/flask/app.py", line 2529, in wsgi_app
    response = self.full_dispatch_request()
               ^^^^^^^^^^^^^^^^^^^^^^^^^^^^
  File "/root/csk-env/lib/python3.11/site-packages/flask/app.py", line 1825, in full_dispatch_request
    rv = self.handle_user_exception(e)
         ^^^^^^^^^^^^^^^^^^^^^^^^^^^^^
  File "/root/csk-env/lib/python3.11/site-packages/flask/app.py", line 1823, in full_dispatch_request
    rv = self.dispatch_request()
         ^^^^^^^^^^^^^^^^^^^^^^^
  File "/root/csk-env/lib/python3.11/site-packages/flask/app.py", line 1799, in dispatch_request
    return self.ensure_sync(self.view_functions[rule.endpoint])(**view_args)
           ^^^^^^^^^^^^^^^^^^^^^^^^^^^^^^^^^^^^^^^^^^^^^^^^^^^^^^^^^^^^^^^^^
  File "/root/csk-main/api/v1/blueprints/post.py", line 84, in post_sale
    sale.save()
  File "/root/csk-main/models/base_model.py", line 34, in save
    models.storage.save()
  File "/root/csk-main/models/engine/db_engine.py", line 24, in save
    self.__session.commit()
  File "/root/csk-env/lib/python3.11/site-packages/sqlalchemy/orm/session.py", line 1454, in commit
    self._transaction.commit(_to_root=self.future)
  File "/root/csk-env/lib/python3.11/site-packages/sqlalchemy/orm/session.py", line 832, in commit
    self._prepare_impl()
  File "/root/csk-env/lib/python3.11/site-packages/sqlalchemy/orm/session.py", line 811, in _prepare_impl
    self.session.flush()
  File "/root/csk-env/lib/python3.11/site-packages/sqlalchemy/orm/session.py", line 3449, in flush
    self._flush(objects)
  File "/root/csk-env/lib/python3.11/site-packages/sqlalchemy/orm/session.py", line 3588, in _flush
    with util.safe_reraise():
  File "/root/csk-env/lib/python3.11/site-packages/sqlalchemy/util/langhelpers.py", line 70, in __exit__
    compat.raise_(
  File "/root/csk-env/lib/python3.11/site-packages/sqlalchemy/util/compat.py", line 211, in raise_
    raise exception
  File "/root/csk-env/lib/python3.11/site-packages/sqlalchemy/orm/session.py", line 3549, in _flush
    flush_context.execute()
  File "/root/csk-env/lib/python3.11/site-packages/sqlalchemy/orm/unitofwork.py", line 456, in execute
    rec.execute(self)
  File "/root/csk-env/lib/python3.11/site-packages/sqlalchemy/orm/unitofwork.py", line 630, in execute
    util.preloaded.orm_persistence.save_obj(
  File "/root/csk-env/lib/python3.11/site-packages/sqlalchemy/orm/persistence.py", line 245, in save_obj
    _emit_insert_statements(
  File "/root/csk-env/lib/python3.11/site-packages/sqlalchemy/orm/persistence.py", line 1097, in _emit_insert_statements
    c = connection._execute_20(
        ^^^^^^^^^^^^^^^^^^^^^^^
  File "/root/csk-env/lib/python3.11/site-packages/sqlalchemy/engine/base.py", line 1710, in _execute_20
    return meth(self, args_10style, kwargs_10style, execution_options)
           ^^^^^^^^^^^^^^^^^^^^^^^^^^^^^^^^^^^^^^^^^^^^^^^^^^^^^^^^^^^
  File "/root/csk-env/lib/python3.11/site-packages/sqlalchemy/sql/elements.py", line 334, in _execute_on_connection
    return connection._execute_clauseelement(
           ^^^^^^^^^^^^^^^^^^^^^^^^^^^^^^^^^^
  File "/root/csk-env/lib/python3.11/site-packages/sqlalchemy/engine/base.py", line 1577, in _execute_clauseelement
    ret = self._execute_context(
          ^^^^^^^^^^^^^^^^^^^^^^
  File "/root/csk-env/lib/python3.11/site-packages/sqlalchemy/engine/base.py", line 1953, in _execute_context
    self._handle_dbapi_exception(
  File "/root/csk-env/lib/python3.11/site-packages/sqlalchemy/engine/base.py", line 2134, in _handle_dbapi_exception
    util.raise_(
  File "/root/csk-env/lib/python3.11/site-packages/sqlalchemy/util/compat.py", line 211, in raise_
    raise exception
  File "/root/csk-env/lib/python3.11/site-packages/sqlalchemy/engine/base.py", line 1910, in _execute_context
    self.dialect.do_execute(
  File "/root/csk-env/lib/python3.11/site-packages/sqlalchemy/engine/default.py", line 736, in do_execute
    cursor.execute(statement, parameters)
  File "/root/csk-env/lib/python3.11/site-packages/MySQLdb/cursors.py", line 179, in execute
    res = self._query(mogrified_query)
          ^^^^^^^^^^^^^^^^^^^^^^^^^^^^
  File "/root/csk-env/lib/python3.11/site-packages/MySQLdb/cursors.py", line 330, in _query
    db.query(q)
  File "/root/csk-env/lib/python3.11/site-packages/MySQLdb/connections.py", line 261, in query
    _mysql.connection.query(self, query)
sqlalchemy.exc.OperationalError: (MySQLdb.OperationalError) (1644, 'Item not found in inventory table')
[SQL: INSERT INTO sale_weekly (id, item_name, quantity, price, user_name, payment_method, time_stamp) VALUES (%s, %s, %s, %s, %s, %s, %s)]
[parameters: ('e9c8e9d7-2e78-4e00-bcdf-22951a0c3958', 'Cap ', 1, 8000, 'Muvunyi_Jimmy', 'Cash', datetime.datetime(2024, 8, 19, 18, 4, 34, 525671))]
(Background on this error at: https://sqlalche.me/e/14/e3q8)
[2024-08-30 13:56:25,526] ERROR in app: Exception on /api/v1/post/new_item [POST]
Traceback (most recent call last):
  File "/root/csk-env/lib/python3.11/site-packages/sqlalchemy/engine/base.py", line 1910, in _execute_context
    self.dialect.do_execute(
  File "/root/csk-env/lib/python3.11/site-packages/sqlalchemy/engine/default.py", line 736, in do_execute
    cursor.execute(statement, parameters)
  File "/root/csk-env/lib/python3.11/site-packages/MySQLdb/cursors.py", line 179, in execute
    res = self._query(mogrified_query)
          ^^^^^^^^^^^^^^^^^^^^^^^^^^^^
  File "/root/csk-env/lib/python3.11/site-packages/MySQLdb/cursors.py", line 330, in _query
    db.query(q)
  File "/root/csk-env/lib/python3.11/site-packages/MySQLdb/connections.py", line 261, in query
    _mysql.connection.query(self, query)
MySQLdb.IntegrityError: (1062, "Duplicate entry 'Football Boots' for key 'inventory.PRIMARY'")

The above exception was the direct cause of the following exception:

Traceback (most recent call last):
  File "/root/csk-env/lib/python3.11/site-packages/flask/app.py", line 2529, in wsgi_app
    response = self.full_dispatch_request()
               ^^^^^^^^^^^^^^^^^^^^^^^^^^^^
  File "/root/csk-env/lib/python3.11/site-packages/flask/app.py", line 1825, in full_dispatch_request
    rv = self.handle_user_exception(e)
         ^^^^^^^^^^^^^^^^^^^^^^^^^^^^^
  File "/root/csk-env/lib/python3.11/site-packages/flask/app.py", line 1823, in full_dispatch_request
    rv = self.dispatch_request()
         ^^^^^^^^^^^^^^^^^^^^^^^
  File "/root/csk-env/lib/python3.11/site-packages/flask/app.py", line 1799, in dispatch_request
    return self.ensure_sync(self.view_functions[rule.endpoint])(**view_args)
           ^^^^^^^^^^^^^^^^^^^^^^^^^^^^^^^^^^^^^^^^^^^^^^^^^^^^^^^^^^^^^^^^^
  File "/root/csk-main/api/v1/blueprints/post.py", line 36, in post_new_item
    inv.save()
  File "/root/csk-main/models/base_model.py", line 34, in save
    models.storage.save()
  File "/root/csk-main/models/engine/db_engine.py", line 24, in save
    self.__session.commit()
  File "/root/csk-env/lib/python3.11/site-packages/sqlalchemy/orm/session.py", line 1454, in commit
    self._transaction.commit(_to_root=self.future)
  File "/root/csk-env/lib/python3.11/site-packages/sqlalchemy/orm/session.py", line 832, in commit
    self._prepare_impl()
  File "/root/csk-env/lib/python3.11/site-packages/sqlalchemy/orm/session.py", line 811, in _prepare_impl
    self.session.flush()
  File "/root/csk-env/lib/python3.11/site-packages/sqlalchemy/orm/session.py", line 3449, in flush
    self._flush(objects)
  File "/root/csk-env/lib/python3.11/site-packages/sqlalchemy/orm/session.py", line 3588, in _flush
    with util.safe_reraise():
  File "/root/csk-env/lib/python3.11/site-packages/sqlalchemy/util/langhelpers.py", line 70, in __exit__
    compat.raise_(
  File "/root/csk-env/lib/python3.11/site-packages/sqlalchemy/util/compat.py", line 211, in raise_
    raise exception
  File "/root/csk-env/lib/python3.11/site-packages/sqlalchemy/orm/session.py", line 3549, in _flush
    flush_context.execute()
  File "/root/csk-env/lib/python3.11/site-packages/sqlalchemy/orm/unitofwork.py", line 456, in execute
    rec.execute(self)
  File "/root/csk-env/lib/python3.11/site-packages/sqlalchemy/orm/unitofwork.py", line 630, in execute
    util.preloaded.orm_persistence.save_obj(
  File "/root/csk-env/lib/python3.11/site-packages/sqlalchemy/orm/persistence.py", line 245, in save_obj
    _emit_insert_statements(
  File "/root/csk-env/lib/python3.11/site-packages/sqlalchemy/orm/persistence.py", line 1097, in _emit_insert_statements
    c = connection._execute_20(
        ^^^^^^^^^^^^^^^^^^^^^^^
  File "/root/csk-env/lib/python3.11/site-packages/sqlalchemy/engine/base.py", line 1710, in _execute_20
    return meth(self, args_10style, kwargs_10style, execution_options)
           ^^^^^^^^^^^^^^^^^^^^^^^^^^^^^^^^^^^^^^^^^^^^^^^^^^^^^^^^^^^
  File "/root/csk-env/lib/python3.11/site-packages/sqlalchemy/sql/elements.py", line 334, in _execute_on_connection
    return connection._execute_clauseelement(
           ^^^^^^^^^^^^^^^^^^^^^^^^^^^^^^^^^^
  File "/root/csk-env/lib/python3.11/site-packages/sqlalchemy/engine/base.py", line 1577, in _execute_clauseelement
    ret = self._execute_context(
          ^^^^^^^^^^^^^^^^^^^^^^
  File "/root/csk-env/lib/python3.11/site-packages/sqlalchemy/engine/base.py", line 1953, in _execute_context
    self._handle_dbapi_exception(
  File "/root/csk-env/lib/python3.11/site-packages/sqlalchemy/engine/base.py", line 2134, in _handle_dbapi_exception
    util.raise_(
  File "/root/csk-env/lib/python3.11/site-packages/sqlalchemy/util/compat.py", line 211, in raise_
    raise exception
  File "/root/csk-env/lib/python3.11/site-packages/sqlalchemy/engine/base.py", line 1910, in _execute_context
    self.dialect.do_execute(
  File "/root/csk-env/lib/python3.11/site-packages/sqlalchemy/engine/default.py", line 736, in do_execute
    cursor.execute(statement, parameters)
  File "/root/csk-env/lib/python3.11/site-packages/MySQLdb/cursors.py", line 179, in execute
    res = self._query(mogrified_query)
          ^^^^^^^^^^^^^^^^^^^^^^^^^^^^
  File "/root/csk-env/lib/python3.11/site-packages/MySQLdb/cursors.py", line 330, in _query
    db.query(q)
  File "/root/csk-env/lib/python3.11/site-packages/MySQLdb/connections.py", line 261, in query
    _mysql.connection.query(self, query)
sqlalchemy.exc.IntegrityError: (MySQLdb.IntegrityError) (1062, "Duplicate entry 'Football Boots' for key 'inventory.PRIMARY'")
[SQL: INSERT INTO inventory (id, name, category_name, inventory_quantity, incoming_time_stamp) VALUES (%s, %s, %s, %s, %s)]
[parameters: ('ab8fbe32-e806-4a12-891d-910566424d39', 'Football Boots', 'Football', 6, datetime.datetime(2024, 8, 30, 13, 56, 25, 523035))]
(Background on this error at: https://sqlalche.me/e/14/gkpj)
[2024-09-12 17:50:18,322] ERROR in app: Exception on /api/v1/post/sale [POST]
Traceback (most recent call last):
  File "/root/csk-env/lib/python3.11/site-packages/sqlalchemy/engine/base.py", line 1910, in _execute_context
    self.dialect.do_execute(
  File "/root/csk-env/lib/python3.11/site-packages/sqlalchemy/engine/default.py", line 736, in do_execute
    cursor.execute(statement, parameters)
  File "/root/csk-env/lib/python3.11/site-packages/MySQLdb/cursors.py", line 179, in execute
    res = self._query(mogrified_query)
          ^^^^^^^^^^^^^^^^^^^^^^^^^^^^
  File "/root/csk-env/lib/python3.11/site-packages/MySQLdb/cursors.py", line 330, in _query
    db.query(q)
  File "/root/csk-env/lib/python3.11/site-packages/MySQLdb/connections.py", line 261, in query
    _mysql.connection.query(self, query)
MySQLdb.OperationalError: (1644, 'Item not found in inventory table')

The above exception was the direct cause of the following exception:

Traceback (most recent call last):
  File "/root/csk-env/lib/python3.11/site-packages/flask/app.py", line 2529, in wsgi_app
    response = self.full_dispatch_request()
               ^^^^^^^^^^^^^^^^^^^^^^^^^^^^
  File "/root/csk-env/lib/python3.11/site-packages/flask/app.py", line 1825, in full_dispatch_request
    rv = self.handle_user_exception(e)
         ^^^^^^^^^^^^^^^^^^^^^^^^^^^^^
  File "/root/csk-env/lib/python3.11/site-packages/flask/app.py", line 1823, in full_dispatch_request
    rv = self.dispatch_request()
         ^^^^^^^^^^^^^^^^^^^^^^^
  File "/root/csk-env/lib/python3.11/site-packages/flask/app.py", line 1799, in dispatch_request
    return self.ensure_sync(self.view_functions[rule.endpoint])(**view_args)
           ^^^^^^^^^^^^^^^^^^^^^^^^^^^^^^^^^^^^^^^^^^^^^^^^^^^^^^^^^^^^^^^^^
  File "/root/csk-main/api/v1/blueprints/post.py", line 84, in post_sale
    sale.save()
  File "/root/csk-main/models/base_model.py", line 34, in save
    models.storage.save()
  File "/root/csk-main/models/engine/db_engine.py", line 24, in save
    self.__session.commit()
  File "/root/csk-env/lib/python3.11/site-packages/sqlalchemy/orm/session.py", line 1454, in commit
    self._transaction.commit(_to_root=self.future)
  File "/root/csk-env/lib/python3.11/site-packages/sqlalchemy/orm/session.py", line 832, in commit
    self._prepare_impl()
  File "/root/csk-env/lib/python3.11/site-packages/sqlalchemy/orm/session.py", line 811, in _prepare_impl
    self.session.flush()
  File "/root/csk-env/lib/python3.11/site-packages/sqlalchemy/orm/session.py", line 3449, in flush
    self._flush(objects)
  File "/root/csk-env/lib/python3.11/site-packages/sqlalchemy/orm/session.py", line 3588, in _flush
    with util.safe_reraise():
  File "/root/csk-env/lib/python3.11/site-packages/sqlalchemy/util/langhelpers.py", line 70, in __exit__
    compat.raise_(
  File "/root/csk-env/lib/python3.11/site-packages/sqlalchemy/util/compat.py", line 211, in raise_
    raise exception
  File "/root/csk-env/lib/python3.11/site-packages/sqlalchemy/orm/session.py", line 3549, in _flush
    flush_context.execute()
  File "/root/csk-env/lib/python3.11/site-packages/sqlalchemy/orm/unitofwork.py", line 456, in execute
    rec.execute(self)
  File "/root/csk-env/lib/python3.11/site-packages/sqlalchemy/orm/unitofwork.py", line 630, in execute
    util.preloaded.orm_persistence.save_obj(
  File "/root/csk-env/lib/python3.11/site-packages/sqlalchemy/orm/persistence.py", line 245, in save_obj
    _emit_insert_statements(
  File "/root/csk-env/lib/python3.11/site-packages/sqlalchemy/orm/persistence.py", line 1097, in _emit_insert_statements
    c = connection._execute_20(
        ^^^^^^^^^^^^^^^^^^^^^^^
  File "/root/csk-env/lib/python3.11/site-packages/sqlalchemy/engine/base.py", line 1710, in _execute_20
    return meth(self, args_10style, kwargs_10style, execution_options)
           ^^^^^^^^^^^^^^^^^^^^^^^^^^^^^^^^^^^^^^^^^^^^^^^^^^^^^^^^^^^
  File "/root/csk-env/lib/python3.11/site-packages/sqlalchemy/sql/elements.py", line 334, in _execute_on_connection
    return connection._execute_clauseelement(
           ^^^^^^^^^^^^^^^^^^^^^^^^^^^^^^^^^^
  File "/root/csk-env/lib/python3.11/site-packages/sqlalchemy/engine/base.py", line 1577, in _execute_clauseelement
    ret = self._execute_context(
          ^^^^^^^^^^^^^^^^^^^^^^
  File "/root/csk-env/lib/python3.11/site-packages/sqlalchemy/engine/base.py", line 1953, in _execute_context
    self._handle_dbapi_exception(
  File "/root/csk-env/lib/python3.11/site-packages/sqlalchemy/engine/base.py", line 2134, in _handle_dbapi_exception
    util.raise_(
  File "/root/csk-env/lib/python3.11/site-packages/sqlalchemy/util/compat.py", line 211, in raise_
    raise exception
  File "/root/csk-env/lib/python3.11/site-packages/sqlalchemy/engine/base.py", line 1910, in _execute_context
    self.dialect.do_execute(
  File "/root/csk-env/lib/python3.11/site-packages/sqlalchemy/engine/default.py", line 736, in do_execute
    cursor.execute(statement, parameters)
  File "/root/csk-env/lib/python3.11/site-packages/MySQLdb/cursors.py", line 179, in execute
    res = self._query(mogrified_query)
          ^^^^^^^^^^^^^^^^^^^^^^^^^^^^
  File "/root/csk-env/lib/python3.11/site-packages/MySQLdb/cursors.py", line 330, in _query
    db.query(q)
  File "/root/csk-env/lib/python3.11/site-packages/MySQLdb/connections.py", line 261, in query
    _mysql.connection.query(self, query)
sqlalchemy.exc.OperationalError: (MySQLdb.OperationalError) (1644, 'Item not found in inventory table')
[SQL: INSERT INTO sale_weekly (id, item_name, quantity, price, user_name, payment_method, time_stamp) VALUES (%s, %s, %s, %s, %s, %s, %s)]
[parameters: ('4c950130-49a3-42a6-8aec-59e7da67fb80', 'Training ', 1, 50000, 'Muvunyi_Jimmy', 'Mobile Money', datetime.datetime(2024, 9, 12, 17, 50, 18, 319547))]
(Background on this error at: https://sqlalche.me/e/14/e3q8)
