[2024-07-29 20:12:42 +0200] [61413] [INFO] Starting gunicorn 22.0.0
[2024-07-29 20:12:42 +0200] [61413] [INFO] Listening at: http://0.0.0.0:5001 (61413)
[2024-07-29 20:12:42 +0200] [61413] [INFO] Using worker: sync
[2024-07-29 20:12:42 +0200] [61414] [INFO] Booting worker with pid: 61414
[2024-07-29 20:12:42 +0200] [61415] [INFO] Booting worker with pid: 61415
[2024-07-29 20:12:42 +0200] [61416] [INFO] Booting worker with pid: 61416
[2024-07-29 20:36:45,606] ERROR in app: Exception on /home [GET]
Traceback (most recent call last):
  File "/root/csk-env/lib/python3.11/site-packages/urllib3/connection.py", line 196, in _new_conn
    sock = connection.create_connection(
           ^^^^^^^^^^^^^^^^^^^^^^^^^^^^^
  File "/root/csk-env/lib/python3.11/site-packages/urllib3/util/connection.py", line 85, in create_connection
    raise err
  File "/root/csk-env/lib/python3.11/site-packages/urllib3/util/connection.py", line 73, in create_connection
    sock.connect(sa)
ConnectionRefusedError: [Errno 111] Connection refused

The above exception was the direct cause of the following exception:

Traceback (most recent call last):
  File "/root/csk-env/lib/python3.11/site-packages/urllib3/connectionpool.py", line 789, in urlopen
    response = self._make_request(
               ^^^^^^^^^^^^^^^^^^^
  File "/root/csk-env/lib/python3.11/site-packages/urllib3/connectionpool.py", line 495, in _make_request
    conn.request(
  File "/root/csk-env/lib/python3.11/site-packages/urllib3/connection.py", line 398, in request
    self.endheaders()
  File "/usr/lib/python3.11/http/client.py", line 1298, in endheaders
    self._send_output(message_body, encode_chunked=encode_chunked)
  File "/usr/lib/python3.11/http/client.py", line 1058, in _send_output
    self.send(msg)
  File "/usr/lib/python3.11/http/client.py", line 996, in send
    self.connect()
  File "/root/csk-env/lib/python3.11/site-packages/urllib3/connection.py", line 236, in connect
    self.sock = self._new_conn()
                ^^^^^^^^^^^^^^^^
  File "/root/csk-env/lib/python3.11/site-packages/urllib3/connection.py", line 211, in _new_conn
    raise NewConnectionError(
urllib3.exceptions.NewConnectionError: <urllib3.connection.HTTPConnection object at 0x7d1cbf7946d0>: Failed to establish a new connection: [Errno 111] Connection refused

The above exception was the direct cause of the following exception:

Traceback (most recent call last):
  File "/root/csk-env/lib/python3.11/site-packages/requests/adapters.py", line 667, in send
    resp = conn.urlopen(
           ^^^^^^^^^^^^^
  File "/root/csk-env/lib/python3.11/site-packages/urllib3/connectionpool.py", line 843, in urlopen
    retries = retries.increment(
              ^^^^^^^^^^^^^^^^^^
  File "/root/csk-env/lib/python3.11/site-packages/urllib3/util/retry.py", line 519, in increment
    raise MaxRetryError(_pool, url, reason) from reason  # type: ignore[arg-type]
    ^^^^^^^^^^^^^^^^^^^^^^^^^^^^^^^^^^^^^^^^^^^^^^^^^^^
urllib3.exceptions.MaxRetryError: HTTPConnectionPool(host='localhost', port=5000): Max retries exceeded with url: /api/v1/inventory (Caused by NewConnectionError('<urllib3.connection.HTTPConnection object at 0x7d1cbf7946d0>: Failed to establish a new connection: [Errno 111] Connection refused'))

During handling of the above exception, another exception occurred:

Traceback (most recent call last):
  File "/root/csk-env/lib/python3.11/site-packages/flask/app.py", line 2529, in wsgi_app
    response = self.full_dispatch_request()
               ^^^^^^^^^^^^^^^^^^^^^^^^^^^^
  File "/root/csk-env/lib/python3.11/site-packages/flask/app.py", line 1825, in full_dispatch_request
    rv = self.handle_user_exception(e)
         ^^^^^^^^^^^^^^^^^^^^^^^^^^^^^
  File "/root/csk-env/lib/python3.11/site-packages/flask/app.py", line 1823, in full_dispatch_request
    rv = self.dispatch_request()
         ^^^^^^^^^^^^^^^^^^^^^^^
  File "/root/csk-env/lib/python3.11/site-packages/flask/app.py", line 1799, in dispatch_request
    return self.ensure_sync(self.view_functions[rule.endpoint])(**view_args)
           ^^^^^^^^^^^^^^^^^^^^^^^^^^^^^^^^^^^^^^^^^^^^^^^^^^^^^^^^^^^^^^^^^
  File "/root/csk-main/web_flask/app1.py", line 34, in main
    send_inventory=get('{}/inventory'.format(local_api_url)).json()
                   ^^^^^^^^^^^^^^^^^^^^^^^^^^^^^^^^^^^^^^^^^
  File "/root/csk-env/lib/python3.11/site-packages/requests/api.py", line 73, in get
    return request("get", url, params=params, **kwargs)
           ^^^^^^^^^^^^^^^^^^^^^^^^^^^^^^^^^^^^^^^^^^^^
  File "/root/csk-env/lib/python3.11/site-packages/requests/api.py", line 59, in request
    return session.request(method=method, url=url, **kwargs)
           ^^^^^^^^^^^^^^^^^^^^^^^^^^^^^^^^^^^^^^^^^^^^^^^^^
  File "/root/csk-env/lib/python3.11/site-packages/requests/sessions.py", line 589, in request
    resp = self.send(prep, **send_kwargs)
           ^^^^^^^^^^^^^^^^^^^^^^^^^^^^^^
  File "/root/csk-env/lib/python3.11/site-packages/requests/sessions.py", line 703, in send
    r = adapter.send(request, **kwargs)
        ^^^^^^^^^^^^^^^^^^^^^^^^^^^^^^^
  File "/root/csk-env/lib/python3.11/site-packages/requests/adapters.py", line 700, in send
    raise ConnectionError(e, request=request)
requests.exceptions.ConnectionError: HTTPConnectionPool(host='localhost', port=5000): Max retries exceeded with url: /api/v1/inventory (Caused by NewConnectionError('<urllib3.connection.HTTPConnection object at 0x7d1cbf7946d0>: Failed to establish a new connection: [Errno 111] Connection refused'))
[2024-07-29 20:36:50,194] ERROR in app: Exception on /home [GET]
Traceback (most recent call last):
  File "/root/csk-env/lib/python3.11/site-packages/urllib3/connection.py", line 196, in _new_conn
    sock = connection.create_connection(
           ^^^^^^^^^^^^^^^^^^^^^^^^^^^^^
  File "/root/csk-env/lib/python3.11/site-packages/urllib3/util/connection.py", line 85, in create_connection
    raise err
  File "/root/csk-env/lib/python3.11/site-packages/urllib3/util/connection.py", line 73, in create_connection
    sock.connect(sa)
ConnectionRefusedError: [Errno 111] Connection refused

The above exception was the direct cause of the following exception:

Traceback (most recent call last):
  File "/root/csk-env/lib/python3.11/site-packages/urllib3/connectionpool.py", line 789, in urlopen
    response = self._make_request(
               ^^^^^^^^^^^^^^^^^^^
  File "/root/csk-env/lib/python3.11/site-packages/urllib3/connectionpool.py", line 495, in _make_request
    conn.request(
  File "/root/csk-env/lib/python3.11/site-packages/urllib3/connection.py", line 398, in request
    self.endheaders()
  File "/usr/lib/python3.11/http/client.py", line 1298, in endheaders
    self._send_output(message_body, encode_chunked=encode_chunked)
  File "/usr/lib/python3.11/http/client.py", line 1058, in _send_output
    self.send(msg)
  File "/usr/lib/python3.11/http/client.py", line 996, in send
    self.connect()
  File "/root/csk-env/lib/python3.11/site-packages/urllib3/connection.py", line 236, in connect
    self.sock = self._new_conn()
                ^^^^^^^^^^^^^^^^
  File "/root/csk-env/lib/python3.11/site-packages/urllib3/connection.py", line 211, in _new_conn
    raise NewConnectionError(
urllib3.exceptions.NewConnectionError: <urllib3.connection.HTTPConnection object at 0x7d1cbf85c1d0>: Failed to establish a new connection: [Errno 111] Connection refused

The above exception was the direct cause of the following exception:

Traceback (most recent call last):
  File "/root/csk-env/lib/python3.11/site-packages/requests/adapters.py", line 667, in send
    resp = conn.urlopen(
           ^^^^^^^^^^^^^
  File "/root/csk-env/lib/python3.11/site-packages/urllib3/connectionpool.py", line 843, in urlopen
    retries = retries.increment(
              ^^^^^^^^^^^^^^^^^^
  File "/root/csk-env/lib/python3.11/site-packages/urllib3/util/retry.py", line 519, in increment
    raise MaxRetryError(_pool, url, reason) from reason  # type: ignore[arg-type]
    ^^^^^^^^^^^^^^^^^^^^^^^^^^^^^^^^^^^^^^^^^^^^^^^^^^^
urllib3.exceptions.MaxRetryError: HTTPConnectionPool(host='localhost', port=5000): Max retries exceeded with url: /api/v1/inventory (Caused by NewConnectionError('<urllib3.connection.HTTPConnection object at 0x7d1cbf85c1d0>: Failed to establish a new connection: [Errno 111] Connection refused'))

During handling of the above exception, another exception occurred:

Traceback (most recent call last):
  File "/root/csk-env/lib/python3.11/site-packages/flask/app.py", line 2529, in wsgi_app
    response = self.full_dispatch_request()
               ^^^^^^^^^^^^^^^^^^^^^^^^^^^^
  File "/root/csk-env/lib/python3.11/site-packages/flask/app.py", line 1825, in full_dispatch_request
    rv = self.handle_user_exception(e)
         ^^^^^^^^^^^^^^^^^^^^^^^^^^^^^
  File "/root/csk-env/lib/python3.11/site-packages/flask/app.py", line 1823, in full_dispatch_request
    rv = self.dispatch_request()
         ^^^^^^^^^^^^^^^^^^^^^^^
  File "/root/csk-env/lib/python3.11/site-packages/flask/app.py", line 1799, in dispatch_request
    return self.ensure_sync(self.view_functions[rule.endpoint])(**view_args)
           ^^^^^^^^^^^^^^^^^^^^^^^^^^^^^^^^^^^^^^^^^^^^^^^^^^^^^^^^^^^^^^^^^
  File "/root/csk-main/web_flask/app1.py", line 34, in main
    send_inventory=get('{}/inventory'.format(local_api_url)).json()
                   ^^^^^^^^^^^^^^^^^^^^^^^^^^^^^^^^^^^^^^^^^
  File "/root/csk-env/lib/python3.11/site-packages/requests/api.py", line 73, in get
    return request("get", url, params=params, **kwargs)
           ^^^^^^^^^^^^^^^^^^^^^^^^^^^^^^^^^^^^^^^^^^^^
  File "/root/csk-env/lib/python3.11/site-packages/requests/api.py", line 59, in request
    return session.request(method=method, url=url, **kwargs)
           ^^^^^^^^^^^^^^^^^^^^^^^^^^^^^^^^^^^^^^^^^^^^^^^^^
  File "/root/csk-env/lib/python3.11/site-packages/requests/sessions.py", line 589, in request
    resp = self.send(prep, **send_kwargs)
           ^^^^^^^^^^^^^^^^^^^^^^^^^^^^^^
  File "/root/csk-env/lib/python3.11/site-packages/requests/sessions.py", line 703, in send
    r = adapter.send(request, **kwargs)
        ^^^^^^^^^^^^^^^^^^^^^^^^^^^^^^^
  File "/root/csk-env/lib/python3.11/site-packages/requests/adapters.py", line 700, in send
    raise ConnectionError(e, request=request)
requests.exceptions.ConnectionError: HTTPConnectionPool(host='localhost', port=5000): Max retries exceeded with url: /api/v1/inventory (Caused by NewConnectionError('<urllib3.connection.HTTPConnection object at 0x7d1cbf85c1d0>: Failed to establish a new connection: [Errno 111] Connection refused'))
[2024-07-29 20:36:51,884] ERROR in app: Exception on /home [GET]
Traceback (most recent call last):
  File "/root/csk-env/lib/python3.11/site-packages/urllib3/connection.py", line 196, in _new_conn
    sock = connection.create_connection(
           ^^^^^^^^^^^^^^^^^^^^^^^^^^^^^
  File "/root/csk-env/lib/python3.11/site-packages/urllib3/util/connection.py", line 85, in create_connection
    raise err
  File "/root/csk-env/lib/python3.11/site-packages/urllib3/util/connection.py", line 73, in create_connection
    sock.connect(sa)
ConnectionRefusedError: [Errno 111] Connection refused

The above exception was the direct cause of the following exception:

Traceback (most recent call last):
  File "/root/csk-env/lib/python3.11/site-packages/urllib3/connectionpool.py", line 789, in urlopen
    response = self._make_request(
               ^^^^^^^^^^^^^^^^^^^
  File "/root/csk-env/lib/python3.11/site-packages/urllib3/connectionpool.py", line 495, in _make_request
    conn.request(
  File "/root/csk-env/lib/python3.11/site-packages/urllib3/connection.py", line 398, in request
    self.endheaders()
  File "/usr/lib/python3.11/http/client.py", line 1298, in endheaders
    self._send_output(message_body, encode_chunked=encode_chunked)
  File "/usr/lib/python3.11/http/client.py", line 1058, in _send_output
    self.send(msg)
  File "/usr/lib/python3.11/http/client.py", line 996, in send
    self.connect()
  File "/root/csk-env/lib/python3.11/site-packages/urllib3/connection.py", line 236, in connect
    self.sock = self._new_conn()
                ^^^^^^^^^^^^^^^^
  File "/root/csk-env/lib/python3.11/site-packages/urllib3/connection.py", line 211, in _new_conn
    raise NewConnectionError(
urllib3.exceptions.NewConnectionError: <urllib3.connection.HTTPConnection object at 0x7d1cbf843590>: Failed to establish a new connection: [Errno 111] Connection refused

The above exception was the direct cause of the following exception:

Traceback (most recent call last):
  File "/root/csk-env/lib/python3.11/site-packages/requests/adapters.py", line 667, in send
    resp = conn.urlopen(
           ^^^^^^^^^^^^^
  File "/root/csk-env/lib/python3.11/site-packages/urllib3/connectionpool.py", line 843, in urlopen
    retries = retries.increment(
              ^^^^^^^^^^^^^^^^^^
  File "/root/csk-env/lib/python3.11/site-packages/urllib3/util/retry.py", line 519, in increment
    raise MaxRetryError(_pool, url, reason) from reason  # type: ignore[arg-type]
    ^^^^^^^^^^^^^^^^^^^^^^^^^^^^^^^^^^^^^^^^^^^^^^^^^^^
urllib3.exceptions.MaxRetryError: HTTPConnectionPool(host='localhost', port=5000): Max retries exceeded with url: /api/v1/inventory (Caused by NewConnectionError('<urllib3.connection.HTTPConnection object at 0x7d1cbf843590>: Failed to establish a new connection: [Errno 111] Connection refused'))

During handling of the above exception, another exception occurred:

Traceback (most recent call last):
  File "/root/csk-env/lib/python3.11/site-packages/flask/app.py", line 2529, in wsgi_app
    response = self.full_dispatch_request()
               ^^^^^^^^^^^^^^^^^^^^^^^^^^^^
  File "/root/csk-env/lib/python3.11/site-packages/flask/app.py", line 1825, in full_dispatch_request
    rv = self.handle_user_exception(e)
         ^^^^^^^^^^^^^^^^^^^^^^^^^^^^^
  File "/root/csk-env/lib/python3.11/site-packages/flask/app.py", line 1823, in full_dispatch_request
    rv = self.dispatch_request()
         ^^^^^^^^^^^^^^^^^^^^^^^
  File "/root/csk-env/lib/python3.11/site-packages/flask/app.py", line 1799, in dispatch_request
    return self.ensure_sync(self.view_functions[rule.endpoint])(**view_args)
           ^^^^^^^^^^^^^^^^^^^^^^^^^^^^^^^^^^^^^^^^^^^^^^^^^^^^^^^^^^^^^^^^^
  File "/root/csk-main/web_flask/app1.py", line 34, in main
    send_inventory=get('{}/inventory'.format(local_api_url)).json()
                   ^^^^^^^^^^^^^^^^^^^^^^^^^^^^^^^^^^^^^^^^^
  File "/root/csk-env/lib/python3.11/site-packages/requests/api.py", line 73, in get
    return request("get", url, params=params, **kwargs)
           ^^^^^^^^^^^^^^^^^^^^^^^^^^^^^^^^^^^^^^^^^^^^
  File "/root/csk-env/lib/python3.11/site-packages/requests/api.py", line 59, in request
    return session.request(method=method, url=url, **kwargs)
           ^^^^^^^^^^^^^^^^^^^^^^^^^^^^^^^^^^^^^^^^^^^^^^^^^
  File "/root/csk-env/lib/python3.11/site-packages/requests/sessions.py", line 589, in request
    resp = self.send(prep, **send_kwargs)
           ^^^^^^^^^^^^^^^^^^^^^^^^^^^^^^
  File "/root/csk-env/lib/python3.11/site-packages/requests/sessions.py", line 703, in send
    r = adapter.send(request, **kwargs)
        ^^^^^^^^^^^^^^^^^^^^^^^^^^^^^^^
  File "/root/csk-env/lib/python3.11/site-packages/requests/adapters.py", line 700, in send
    raise ConnectionError(e, request=request)
requests.exceptions.ConnectionError: HTTPConnectionPool(host='localhost', port=5000): Max retries exceeded with url: /api/v1/inventory (Caused by NewConnectionError('<urllib3.connection.HTTPConnection object at 0x7d1cbf843590>: Failed to establish a new connection: [Errno 111] Connection refused'))
[2024-07-30 16:00:24 +0200] [61413] [INFO] Handling signal: term
[2024-07-30 16:00:24 +0200] [61416] [INFO] Worker exiting (pid: 61416)
[2024-07-30 16:00:24 +0200] [61415] [INFO] Worker exiting (pid: 61415)
[2024-07-30 16:00:24 +0200] [61414] [INFO] Worker exiting (pid: 61414)
[2024-07-30 16:00:25 +0200] [61413] [INFO] Shutting down: Master
[2024-07-30 16:00:25 +0200] [69686] [INFO] Starting gunicorn 22.0.0
[2024-07-30 16:00:25 +0200] [69686] [INFO] Listening at: http://0.0.0.0:5001 (69686)
[2024-07-30 16:00:25 +0200] [69686] [INFO] Using worker: sync
[2024-07-30 16:00:25 +0200] [69688] [INFO] Booting worker with pid: 69688
[2024-07-30 16:00:25 +0200] [69689] [INFO] Booting worker with pid: 69689
[2024-07-30 16:00:25 +0200] [69690] [INFO] Booting worker with pid: 69690
[2024-07-30 23:08:02,264] ERROR in app: Exception on /pie [GET]
Traceback (most recent call last):
  File "/root/csk-env/lib/python3.11/site-packages/flask/app.py", line 2529, in wsgi_app
    response = self.full_dispatch_request()
               ^^^^^^^^^^^^^^^^^^^^^^^^^^^^
  File "/root/csk-env/lib/python3.11/site-packages/flask/app.py", line 1825, in full_dispatch_request
    rv = self.handle_user_exception(e)
         ^^^^^^^^^^^^^^^^^^^^^^^^^^^^^
  File "/root/csk-env/lib/python3.11/site-packages/flask/app.py", line 1823, in full_dispatch_request
    rv = self.dispatch_request()
         ^^^^^^^^^^^^^^^^^^^^^^^
  File "/root/csk-env/lib/python3.11/site-packages/flask/app.py", line 1799, in dispatch_request
    return self.ensure_sync(self.view_functions[rule.endpoint])(**view_args)
           ^^^^^^^^^^^^^^^^^^^^^^^^^^^^^^^^^^^^^^^^^^^^^^^^^^^^^^^^^^^^^^^^^
  File "/root/csk-main/web_flask/app1.py", line 50, in pie
    if session['user'] != 'Ashimwe_Geoffrey':
       ~~~~~~~^^^^^^^^
  File "/root/csk-env/lib/python3.11/site-packages/flask/sessions.py", line 80, in __getitem__
    return super().__getitem__(key)
           ^^^^^^^^^^^^^^^^^^^^^^^^
KeyError: 'user'
[2024-07-30 23:11:03,435] ERROR in app: Exception on /pie [GET]
Traceback (most recent call last):
  File "/root/csk-env/lib/python3.11/site-packages/flask/app.py", line 2529, in wsgi_app
    response = self.full_dispatch_request()
               ^^^^^^^^^^^^^^^^^^^^^^^^^^^^
  File "/root/csk-env/lib/python3.11/site-packages/flask/app.py", line 1825, in full_dispatch_request
    rv = self.handle_user_exception(e)
         ^^^^^^^^^^^^^^^^^^^^^^^^^^^^^
  File "/root/csk-env/lib/python3.11/site-packages/flask/app.py", line 1823, in full_dispatch_request
    rv = self.dispatch_request()
         ^^^^^^^^^^^^^^^^^^^^^^^
  File "/root/csk-env/lib/python3.11/site-packages/flask/app.py", line 1799, in dispatch_request
    return self.ensure_sync(self.view_functions[rule.endpoint])(**view_args)
           ^^^^^^^^^^^^^^^^^^^^^^^^^^^^^^^^^^^^^^^^^^^^^^^^^^^^^^^^^^^^^^^^^
  File "/root/csk-main/web_flask/app1.py", line 50, in pie
    if session['user'] != 'Ashimwe_Geoffrey':
       ~~~~~~~^^^^^^^^
  File "/root/csk-env/lib/python3.11/site-packages/flask/sessions.py", line 80, in __getitem__
    return super().__getitem__(key)
           ^^^^^^^^^^^^^^^^^^^^^^^^
KeyError: 'user'
[2024-07-30 23:11:44 +0200] [69689] [INFO] Worker exiting (pid: 69689)
[2024-07-30 23:11:44 +0200] [69688] [INFO] Worker exiting (pid: 69688)
[2024-07-30 23:11:44 +0200] [69690] [INFO] Worker exiting (pid: 69690)
[2024-07-30 23:11:44 +0200] [69686] [INFO] Handling signal: term
[2024-07-30 23:11:44 +0200] [69686] [ERROR] Worker (pid:69689) was sent SIGTERM!
[2024-07-30 23:11:44 +0200] [69686] [ERROR] Worker (pid:69690) was sent SIGTERM!
[2024-07-30 23:11:44 +0200] [69686] [ERROR] Worker (pid:69688) was sent SIGTERM!
[2024-07-30 23:11:44 +0200] [69686] [INFO] Shutting down: Master
[2024-07-30 23:11:44 +0200] [73590] [INFO] Starting gunicorn 22.0.0
[2024-07-30 23:11:44 +0200] [73590] [INFO] Listening at: http://0.0.0.0:5001 (73590)
[2024-07-30 23:11:44 +0200] [73590] [INFO] Using worker: sync
[2024-07-30 23:11:44 +0200] [73592] [INFO] Booting worker with pid: 73592
[2024-07-30 23:11:44 +0200] [73592] [ERROR] Exception in worker process
Traceback (most recent call last):
  File "/root/csk-env/lib/python3.11/site-packages/gunicorn/arbiter.py", line 609, in spawn_worker
    worker.init_process()
  File "/root/csk-env/lib/python3.11/site-packages/gunicorn/workers/base.py", line 134, in init_process
    self.load_wsgi()
  File "/root/csk-env/lib/python3.11/site-packages/gunicorn/workers/base.py", line 146, in load_wsgi
    self.wsgi = self.app.wsgi()
                ^^^^^^^^^^^^^^^
  File "/root/csk-env/lib/python3.11/site-packages/gunicorn/app/base.py", line 67, in wsgi
    self.callable = self.load()
                    ^^^^^^^^^^^
  File "/root/csk-env/lib/python3.11/site-packages/gunicorn/app/wsgiapp.py", line 58, in load
    return self.load_wsgiapp()
           ^^^^^^^^^^^^^^^^^^^
  File "/root/csk-env/lib/python3.11/site-packages/gunicorn/app/wsgiapp.py", line 48, in load_wsgiapp
    return util.import_app(self.app_uri)
           ^^^^^^^^^^^^^^^^^^^^^^^^^^^^^
  File "/root/csk-env/lib/python3.11/site-packages/gunicorn/util.py", line 371, in import_app
    mod = importlib.import_module(module)
          ^^^^^^^^^^^^^^^^^^^^^^^^^^^^^^^
  File "/usr/lib/python3.11/importlib/__init__.py", line 126, in import_module
    return _bootstrap._gcd_import(name[level:], package, level)
           ^^^^^^^^^^^^^^^^^^^^^^^^^^^^^^^^^^^^^^^^^^^^^^^^^^^^
  File "<frozen importlib._bootstrap>", line 1204, in _gcd_import
  File "<frozen importlib._bootstrap>", line 1176, in _find_and_load
  File "<frozen importlib._bootstrap>", line 1147, in _find_and_load_unlocked
  File "<frozen importlib._bootstrap>", line 690, in _load_unlocked
  File "<frozen importlib._bootstrap_external>", line 936, in exec_module
  File "<frozen importlib._bootstrap_external>", line 1074, in get_code
  File "<frozen importlib._bootstrap_external>", line 1004, in source_to_code
  File "<frozen importlib._bootstrap>", line 241, in _call_with_frames_removed
  File "/root/csk-main/web_flask/app1.py", line 66
    return redirect('/login'
                   ^
SyntaxError: '(' was never closed
[2024-07-30 23:11:44 +0200] [73592] [INFO] Worker exiting (pid: 73592)
[2024-07-30 23:11:44 +0200] [73593] [INFO] Booting worker with pid: 73593
[2024-07-30 23:11:44 +0200] [73593] [ERROR] Exception in worker process
Traceback (most recent call last):
  File "/root/csk-env/lib/python3.11/site-packages/gunicorn/arbiter.py", line 609, in spawn_worker
    worker.init_process()
  File "/root/csk-env/lib/python3.11/site-packages/gunicorn/workers/base.py", line 134, in init_process
    self.load_wsgi()
  File "/root/csk-env/lib/python3.11/site-packages/gunicorn/workers/base.py", line 146, in load_wsgi
    self.wsgi = self.app.wsgi()
                ^^^^^^^^^^^^^^^
  File "/root/csk-env/lib/python3.11/site-packages/gunicorn/app/base.py", line 67, in wsgi
    self.callable = self.load()
                    ^^^^^^^^^^^
  File "/root/csk-env/lib/python3.11/site-packages/gunicorn/app/wsgiapp.py", line 58, in load
    return self.load_wsgiapp()
           ^^^^^^^^^^^^^^^^^^^
  File "/root/csk-env/lib/python3.11/site-packages/gunicorn/app/wsgiapp.py", line 48, in load_wsgiapp
    return util.import_app(self.app_uri)
           ^^^^^^^^^^^^^^^^^^^^^^^^^^^^^
  File "/root/csk-env/lib/python3.11/site-packages/gunicorn/util.py", line 371, in import_app
    mod = importlib.import_module(module)
          ^^^^^^^^^^^^^^^^^^^^^^^^^^^^^^^
  File "/usr/lib/python3.11/importlib/__init__.py", line 126, in import_module
    return _bootstrap._gcd_import(name[level:], package, level)
           ^^^^^^^^^^^^^^^^^^^^^^^^^^^^^^^^^^^^^^^^^^^^^^^^^^^^
  File "<frozen importlib._bootstrap>", line 1204, in _gcd_import
  File "<frozen importlib._bootstrap>", line 1176, in _find_and_load
  File "<frozen importlib._bootstrap>", line 1147, in _find_and_load_unlocked
  File "<frozen importlib._bootstrap>", line 690, in _load_unlocked
  File "<frozen importlib._bootstrap_external>", line 936, in exec_module
  File "<frozen importlib._bootstrap_external>", line 1074, in get_code
  File "<frozen importlib._bootstrap_external>", line 1004, in source_to_code
  File "<frozen importlib._bootstrap>", line 241, in _call_with_frames_removed
  File "/root/csk-main/web_flask/app1.py", line 66
    return redirect('/login'
                   ^
SyntaxError: '(' was never closed
[2024-07-30 23:11:44 +0200] [73593] [INFO] Worker exiting (pid: 73593)
[2024-07-30 23:11:44 +0200] [73590] [ERROR] Worker (pid:73592) exited with code 3
[2024-07-30 23:11:44 +0200] [73590] [ERROR] Worker (pid:73593) was sent SIGTERM!
[2024-07-30 23:11:45 +0200] [73590] [ERROR] Shutting down: Master
[2024-07-30 23:11:45 +0200] [73590] [ERROR] Reason: Worker failed to boot.
[2024-07-30 23:11:53 +0200] [73600] [INFO] Starting gunicorn 22.0.0
[2024-07-30 23:11:53 +0200] [73600] [INFO] Listening at: http://0.0.0.0:5001 (73600)
[2024-07-30 23:11:53 +0200] [73600] [INFO] Using worker: sync
[2024-07-30 23:11:53 +0200] [73601] [INFO] Booting worker with pid: 73601
[2024-07-30 23:11:53 +0200] [73601] [ERROR] Exception in worker process
Traceback (most recent call last):
  File "/root/csk-env/lib/python3.11/site-packages/gunicorn/arbiter.py", line 609, in spawn_worker
    worker.init_process()
  File "/root/csk-env/lib/python3.11/site-packages/gunicorn/workers/base.py", line 134, in init_process
    self.load_wsgi()
  File "/root/csk-env/lib/python3.11/site-packages/gunicorn/workers/base.py", line 146, in load_wsgi
    self.wsgi = self.app.wsgi()
                ^^^^^^^^^^^^^^^
  File "/root/csk-env/lib/python3.11/site-packages/gunicorn/app/base.py", line 67, in wsgi
    self.callable = self.load()
                    ^^^^^^^^^^^
  File "/root/csk-env/lib/python3.11/site-packages/gunicorn/app/wsgiapp.py", line 58, in load
    return self.load_wsgiapp()
           ^^^^^^^^^^^^^^^^^^^
  File "/root/csk-env/lib/python3.11/site-packages/gunicorn/app/wsgiapp.py", line 48, in load_wsgiapp
    return util.import_app(self.app_uri)
           ^^^^^^^^^^^^^^^^^^^^^^^^^^^^^
  File "/root/csk-env/lib/python3.11/site-packages/gunicorn/util.py", line 371, in import_app
    mod = importlib.import_module(module)
          ^^^^^^^^^^^^^^^^^^^^^^^^^^^^^^^
  File "/usr/lib/python3.11/importlib/__init__.py", line 126, in import_module
    return _bootstrap._gcd_import(name[level:], package, level)
           ^^^^^^^^^^^^^^^^^^^^^^^^^^^^^^^^^^^^^^^^^^^^^^^^^^^^
  File "<frozen importlib._bootstrap>", line 1204, in _gcd_import
  File "<frozen importlib._bootstrap>", line 1176, in _find_and_load
  File "<frozen importlib._bootstrap>", line 1147, in _find_and_load_unlocked
  File "<frozen importlib._bootstrap>", line 690, in _load_unlocked
  File "<frozen importlib._bootstrap_external>", line 936, in exec_module
  File "<frozen importlib._bootstrap_external>", line 1074, in get_code
  File "<frozen importlib._bootstrap_external>", line 1004, in source_to_code
  File "<frozen importlib._bootstrap>", line 241, in _call_with_frames_removed
  File "/root/csk-main/web_flask/app1.py", line 66
    return redirect('/login'
                   ^
SyntaxError: '(' was never closed
[2024-07-30 23:11:53 +0200] [73601] [INFO] Worker exiting (pid: 73601)
[2024-07-30 23:11:53 +0200] [73602] [INFO] Booting worker with pid: 73602
[2024-07-30 23:11:53 +0200] [73602] [ERROR] Exception in worker process
Traceback (most recent call last):
  File "/root/csk-env/lib/python3.11/site-packages/gunicorn/arbiter.py", line 609, in spawn_worker
    worker.init_process()
  File "/root/csk-env/lib/python3.11/site-packages/gunicorn/workers/base.py", line 134, in init_process
    self.load_wsgi()
  File "/root/csk-env/lib/python3.11/site-packages/gunicorn/workers/base.py", line 146, in load_wsgi
    self.wsgi = self.app.wsgi()
                ^^^^^^^^^^^^^^^
  File "/root/csk-env/lib/python3.11/site-packages/gunicorn/app/base.py", line 67, in wsgi
    self.callable = self.load()
                    ^^^^^^^^^^^
  File "/root/csk-env/lib/python3.11/site-packages/gunicorn/app/wsgiapp.py", line 58, in load
    return self.load_wsgiapp()
           ^^^^^^^^^^^^^^^^^^^
  File "/root/csk-env/lib/python3.11/site-packages/gunicorn/app/wsgiapp.py", line 48, in load_wsgiapp
    return util.import_app(self.app_uri)
           ^^^^^^^^^^^^^^^^^^^^^^^^^^^^^
  File "/root/csk-env/lib/python3.11/site-packages/gunicorn/util.py", line 371, in import_app
    mod = importlib.import_module(module)
          ^^^^^^^^^^^^^^^^^^^^^^^^^^^^^^^
  File "/usr/lib/python3.11/importlib/__init__.py", line 126, in import_module
    return _bootstrap._gcd_import(name[level:], package, level)
           ^^^^^^^^^^^^^^^^^^^^^^^^^^^^^^^^^^^^^^^^^^^^^^^^^^^^
  File "<frozen importlib._bootstrap>", line 1204, in _gcd_import
  File "<frozen importlib._bootstrap>", line 1176, in _find_and_load
  File "<frozen importlib._bootstrap>", line 1147, in _find_and_load_unlocked
  File "<frozen importlib._bootstrap>", line 690, in _load_unlocked
  File "<frozen importlib._bootstrap_external>", line 936, in exec_module
  File "<frozen importlib._bootstrap_external>", line 1074, in get_code
  File "<frozen importlib._bootstrap_external>", line 1004, in source_to_code
  File "<frozen importlib._bootstrap>", line 241, in _call_with_frames_removed
  File "/root/csk-main/web_flask/app1.py", line 66
    return redirect('/login'
                   ^
SyntaxError: '(' was never closed
[2024-07-30 23:11:53 +0200] [73602] [INFO] Worker exiting (pid: 73602)
[2024-07-30 23:11:53 +0200] [73600] [ERROR] Worker (pid:73601) exited with code 3
[2024-07-30 23:11:53 +0200] [73600] [ERROR] Worker (pid:73602) was sent SIGTERM!
[2024-07-30 23:11:54 +0200] [73600] [ERROR] Shutting down: Master
[2024-07-30 23:11:54 +0200] [73600] [ERROR] Reason: Worker failed to boot.
[2024-07-30 23:12:23 +0200] [73610] [INFO] Starting gunicorn 22.0.0
[2024-07-30 23:12:23 +0200] [73610] [INFO] Listening at: http://0.0.0.0:5001 (73610)
[2024-07-30 23:12:23 +0200] [73610] [INFO] Using worker: sync
[2024-07-30 23:12:23 +0200] [73611] [INFO] Booting worker with pid: 73611
[2024-07-30 23:12:23 +0200] [73611] [ERROR] Exception in worker process
Traceback (most recent call last):
  File "/root/csk-env/lib/python3.11/site-packages/gunicorn/arbiter.py", line 609, in spawn_worker
    worker.init_process()
  File "/root/csk-env/lib/python3.11/site-packages/gunicorn/workers/base.py", line 134, in init_process
    self.load_wsgi()
  File "/root/csk-env/lib/python3.11/site-packages/gunicorn/workers/base.py", line 146, in load_wsgi
    self.wsgi = self.app.wsgi()
                ^^^^^^^^^^^^^^^
  File "/root/csk-env/lib/python3.11/site-packages/gunicorn/app/base.py", line 67, in wsgi
    self.callable = self.load()
                    ^^^^^^^^^^^
  File "/root/csk-env/lib/python3.11/site-packages/gunicorn/app/wsgiapp.py", line 58, in load
    return self.load_wsgiapp()
           ^^^^^^^^^^^^^^^^^^^
  File "/root/csk-env/lib/python3.11/site-packages/gunicorn/app/wsgiapp.py", line 48, in load_wsgiapp
    return util.import_app(self.app_uri)
           ^^^^^^^^^^^^^^^^^^^^^^^^^^^^^
  File "/root/csk-env/lib/python3.11/site-packages/gunicorn/util.py", line 371, in import_app
    mod = importlib.import_module(module)
          ^^^^^^^^^^^^^^^^^^^^^^^^^^^^^^^
  File "/usr/lib/python3.11/importlib/__init__.py", line 126, in import_module
    return _bootstrap._gcd_import(name[level:], package, level)
           ^^^^^^^^^^^^^^^^^^^^^^^^^^^^^^^^^^^^^^^^^^^^^^^^^^^^
  File "<frozen importlib._bootstrap>", line 1204, in _gcd_import
  File "<frozen importlib._bootstrap>", line 1176, in _find_and_load
  File "<frozen importlib._bootstrap>", line 1147, in _find_and_load_unlocked
  File "<frozen importlib._bootstrap>", line 690, in _load_unlocked
  File "<frozen importlib._bootstrap_external>", line 936, in exec_module
  File "<frozen importlib._bootstrap_external>", line 1074, in get_code
  File "<frozen importlib._bootstrap_external>", line 1004, in source_to_code
  File "<frozen importlib._bootstrap>", line 241, in _call_with_frames_removed
  File "/root/csk-main/web_flask/app1.py", line 66
    return redirect('/login'
                   ^
SyntaxError: '(' was never closed
[2024-07-30 23:12:23 +0200] [73611] [INFO] Worker exiting (pid: 73611)
[2024-07-30 23:12:23 +0200] [73610] [ERROR] Worker (pid:73611) exited with code 3
[2024-07-30 23:12:23 +0200] [73610] [ERROR] Shutting down: Master
[2024-07-30 23:12:23 +0200] [73610] [ERROR] Reason: Worker failed to boot.
[2024-07-30 23:12:51 +0200] [73620] [INFO] Starting gunicorn 22.0.0
[2024-07-30 23:12:51 +0200] [73620] [INFO] Listening at: http://0.0.0.0:5001 (73620)
[2024-07-30 23:12:51 +0200] [73620] [INFO] Using worker: sync
[2024-07-30 23:12:51 +0200] [73621] [INFO] Booting worker with pid: 73621
[2024-07-30 23:12:51 +0200] [73622] [INFO] Booting worker with pid: 73622
[2024-07-30 23:12:51 +0200] [73623] [INFO] Booting worker with pid: 73623
[2024-07-30 23:13:20 +0200] [73621] [INFO] Worker exiting (pid: 73621)
[2024-07-30 23:13:20 +0200] [73620] [INFO] Handling signal: term
[2024-07-30 23:13:20 +0200] [73622] [INFO] Worker exiting (pid: 73622)
[2024-07-30 23:13:20 +0200] [73623] [INFO] Worker exiting (pid: 73623)
[2024-07-30 23:13:20 +0200] [73620] [ERROR] Worker (pid:73622) was sent SIGTERM!
[2024-07-30 23:13:20 +0200] [73620] [ERROR] Worker (pid:73623) was sent SIGTERM!
[2024-07-30 23:13:20 +0200] [73620] [ERROR] Worker (pid:73621) was sent SIGTERM!
[2024-07-30 23:13:20 +0200] [73620] [INFO] Shutting down: Master
[2024-07-30 23:13:20 +0200] [73631] [INFO] Starting gunicorn 22.0.0
[2024-07-30 23:13:20 +0200] [73631] [INFO] Listening at: http://0.0.0.0:5001 (73631)
[2024-07-30 23:13:20 +0200] [73631] [INFO] Using worker: sync
[2024-07-30 23:13:20 +0200] [73633] [INFO] Booting worker with pid: 73633
[2024-07-30 23:13:20 +0200] [73634] [INFO] Booting worker with pid: 73634
[2024-07-30 23:13:20 +0200] [73635] [INFO] Booting worker with pid: 73635
[2024-07-30 23:34:16,002] ERROR in app: Exception on /pie [GET]
Traceback (most recent call last):
  File "/root/csk-env/lib/python3.11/site-packages/flask/app.py", line 2529, in wsgi_app
    response = self.full_dispatch_request()
               ^^^^^^^^^^^^^^^^^^^^^^^^^^^^
  File "/root/csk-env/lib/python3.11/site-packages/flask/app.py", line 1825, in full_dispatch_request
    rv = self.handle_user_exception(e)
         ^^^^^^^^^^^^^^^^^^^^^^^^^^^^^
  File "/root/csk-env/lib/python3.11/site-packages/flask/app.py", line 1823, in full_dispatch_request
    rv = self.dispatch_request()
         ^^^^^^^^^^^^^^^^^^^^^^^
  File "/root/csk-env/lib/python3.11/site-packages/flask/app.py", line 1799, in dispatch_request
    return self.ensure_sync(self.view_functions[rule.endpoint])(**view_args)
           ^^^^^^^^^^^^^^^^^^^^^^^^^^^^^^^^^^^^^^^^^^^^^^^^^^^^^^^^^^^^^^^^^
  File "/root/csk-main/web_flask/app1.py", line 50, in pie
    if session['user'] != 'Ashimwe_Geoffrey':
       ~~~~~~~^^^^^^^^
  File "/root/csk-env/lib/python3.11/site-packages/flask/sessions.py", line 80, in __getitem__
    return super().__getitem__(key)
           ^^^^^^^^^^^^^^^^^^^^^^^^
KeyError: 'user'
[2024-07-30 23:36:10 +0200] [73635] [INFO] Worker exiting (pid: 73635)
[2024-07-30 23:36:10 +0200] [73634] [INFO] Worker exiting (pid: 73634)
[2024-07-30 23:36:10 +0200] [73633] [INFO] Worker exiting (pid: 73633)
[2024-07-30 23:36:10 +0200] [73631] [INFO] Handling signal: term
[2024-07-30 23:36:10 +0200] [73631] [ERROR] Worker (pid:73633) was sent SIGTERM!
[2024-07-30 23:36:10 +0200] [73631] [ERROR] Worker (pid:73635) was sent SIGTERM!
[2024-07-30 23:36:10 +0200] [73631] [INFO] Shutting down: Master
[2024-07-30 23:36:10 +0200] [74062] [INFO] Starting gunicorn 22.0.0
[2024-07-30 23:36:10 +0200] [74062] [INFO] Listening at: http://0.0.0.0:5001 (74062)
[2024-07-30 23:36:10 +0200] [74062] [INFO] Using worker: sync
[2024-07-30 23:36:10 +0200] [74066] [INFO] Booting worker with pid: 74066
[2024-07-30 23:36:10 +0200] [74067] [INFO] Booting worker with pid: 74067
[2024-07-30 23:36:10 +0200] [74068] [INFO] Booting worker with pid: 74068
